[30;1m2023-03-09 23:44:20[0m [34;1mINFO    [0m [35mdiscord.client[0m logging in using static token
[30;1m2023-03-09 23:44:21[0m [34;1mINFO    [0m [35mdiscord.gateway[0m Shard ID None has connected to Gateway (Session ID: 3ada0631039dbc8f39ba223f0a49938a).
[30;1m2023-03-09 23:48:19[0m [31mERROR   [0m [35mdiscord.client[0m Attempting a reconnect in 1.85s
[31mTraceback (most recent call last):
  File "C:\Users\David\AppData\Local\Programs\Python\Python310\lib\site-packages\aiohttp\connector.py", line 1152, in _create_direct_connection
    hosts = await asyncio.shield(host_resolved)
  File "C:\Users\David\AppData\Local\Programs\Python\Python310\lib\site-packages\aiohttp\connector.py", line 874, in _resolve_host
    addrs = await self._resolver.resolve(host, port, family=self._family)
  File "C:\Users\David\AppData\Local\Programs\Python\Python310\lib\site-packages\aiohttp\resolver.py", line 33, in resolve
    infos = await self._loop.getaddrinfo(
  File "C:\Users\David\AppData\Local\Programs\Python\Python310\lib\asyncio\base_events.py", line 860, in getaddrinfo
    return await self.run_in_executor(
  File "C:\Users\David\AppData\Local\Programs\Python\Python310\lib\concurrent\futures\thread.py", line 58, in run
    result = self.fn(*self.args, **self.kwargs)
  File "C:\Users\David\AppData\Local\Programs\Python\Python310\lib\socket.py", line 955, in getaddrinfo
    for res in _socket.getaddrinfo(host, port, family, type, proto, flags):
socket.gaierror: [Errno 11001] getaddrinfo failed

The above exception was the direct cause of the following exception:

Traceback (most recent call last):
  File "C:\Users\David\AppData\Local\Programs\Python\Python310\lib\site-packages\discord\client.py", line 624, in connect
    self.ws = await asyncio.wait_for(coro, timeout=60.0)
  File "C:\Users\David\AppData\Local\Programs\Python\Python310\lib\asyncio\tasks.py", line 445, in wait_for
    return fut.result()
  File "C:\Users\David\AppData\Local\Programs\Python\Python310\lib\site-packages\discord\gateway.py", line 372, in from_client
    socket = await client.http.ws_connect(str(url))
  File "C:\Users\David\AppData\Local\Programs\Python\Python310\lib\site-packages\discord\http.py", line 536, in ws_connect
    return await self.__session.ws_connect(url, **kwargs)
  File "C:\Users\David\AppData\Local\Programs\Python\Python310\lib\site-packages\aiohttp\client.py", line 779, in _ws_connect
    resp = await self.request(
  File "C:\Users\David\AppData\Local\Programs\Python\Python310\lib\site-packages\aiohttp\client.py", line 536, in _request
    conn = await self._connector.connect(
  File "C:\Users\David\AppData\Local\Programs\Python\Python310\lib\site-packages\aiohttp\connector.py", line 540, in connect
    proto = await self._create_connection(req, traces, timeout)
  File "C:\Users\David\AppData\Local\Programs\Python\Python310\lib\site-packages\aiohttp\connector.py", line 901, in _create_connection
    _, proto = await self._create_direct_connection(req, traces, timeout)
  File "C:\Users\David\AppData\Local\Programs\Python\Python310\lib\site-packages\aiohttp\connector.py", line 1166, in _create_direct_connection
    raise ClientConnectorError(req.connection_key, exc) from exc
aiohttp.client_exceptions.ClientConnectorError: Cannot connect to host gateway-us-east1-b.discord.gg:443 ssl:default [getaddrinfo failed][0m
[30;1m2023-03-09 23:48:21[0m [34;1mINFO    [0m [35mdiscord.gateway[0m Shard ID None has successfully RESUMED session 3ada0631039dbc8f39ba223f0a49938a.
